test_anagram (__main__.TestExercice) ... ERROR
test_doubles (__main__.TestExercice) ... FAIL
test_frequence (__main__.TestExercice) ... ERROR
test_grades (__main__.TestExercice) ... FAIL
test_order (__main__.TestExercice) ... ERROR

======================================================================
ERROR: test_anagram (__main__.TestExercice)
----------------------------------------------------------------------
Traceback (most recent call last):
  File "test_exercice.py", line 35, in test_anagram
    output = [exercice.anagrams(v) for v in words]
  File "test_exercice.py", line 35, in <listcomp>
    output = [exercice.anagrams(v) for v in words]
  File "/home/runner/work/2021a-c01-ch6-1-exercices-YuliiaOz/2021a-c01-ch6-1-exercices-YuliiaOz/exercice.py", line 21, in anagrams
    chaine1 = list(input())
EOFError: EOF when reading a line

======================================================================
ERROR: test_frequence (__main__.TestExercice)
----------------------------------------------------------------------
Traceback (most recent call last):
  File "test_exercice.py", line 77, in test_frequence
    output = [exercice.frequence(s) for s in sentences]
  File "test_exercice.py", line 77, in <listcomp>
    output = [exercice.frequence(s) for s in sentences]
  File "/home/runner/work/2021a-c01-ch6-1-exercices-YuliiaOz/2021a-c01-ch6-1-exercices-YuliiaOz/exercice.py", line 67, in frequence
    sorted_keys = sorted(frequency, key=frequency.__getitem__(), reverse=True)
TypeError: __getitem__() takes exactly one argument (0 given)

======================================================================
ERROR: test_order (__main__.TestExercice)
----------------------------------------------------------------------
Traceback (most recent call last):
  File "test_exercice.py", line 19, in test_order
    output = [exercice.order(v) for v in values]
  File "test_exercice.py", line 19, in <listcomp>
    output = [exercice.order(v) for v in values]
  File "/home/runner/work/2021a-c01-ch6-1-exercices-YuliiaOz/2021a-c01-ch6-1-exercices-YuliiaOz/exercice.py", line 11, in order
    liste_de_valeurs.sort()
UnboundLocalError: local variable 'liste_de_valeurs' referenced before assignment

======================================================================
FAIL: test_doubles (__main__.TestExercice)
----------------------------------------------------------------------
Traceback (most recent call last):
  File "test_exercice.py", line 52, in test_doubles
    self.assertListEqual(
AssertionError: Lists differ: [True, True] != [False, True]

First differing element 0:
True
False

- [True, True]
+ [False, True] : Erreur dans les doublons

======================================================================
FAIL: test_grades (__main__.TestExercice)
----------------------------------------------------------------------
Traceback (most recent call last):
  File "test_exercice.py", line 65, in test_grades
    self.assertDictEqual(
AssertionError: {} != {'Sam': 85}
- {}
+ {'Sam': 85} : Erreur dans les notes

----------------------------------------------------------------------
Ran 5 tests in 0.001s

FAILED (failures=2, errors=3)
